<?xml version="1.0" ?>
<!-- =================================================================================== -->
<!-- |    This document was autogenerated by xacro from yumi.urdf.xacro                | -->
<!-- |    EDITING THIS FILE BY HAND IS NOT RECOMMENDED                                 | -->
<!-- =================================================================================== -->
<robot name="yumi" xmlns:xacro="http://www.ros.org/wiki/xacro">
  <material name="Black">
    <color rgba="0.0 0.0 0.0 1.0"/>
  </material>
  <material name="Blue">
    <color rgba="0.0 0.0 0.8 1.0"/>
  </material>
  <material name="Green">
    <color rgba="0.0 0.8 0.0 1.0"/>
  </material>
  <material name="Grey">
    <color rgba="0.5 0.5 0.5 1.0"/>
  </material>
  <material name="Light_Grey">
    <color rgba="0.8 0.8 0.8 1.0"/>
  </material>
  <material name="Ivory">
    <color rgba="1.0 1.0 0.94 1.0"/>
  </material>
  <material name="Orange">
    <color rgba="1.0 0.423529411765 0.0392156862745 1.0"/>
  </material>
  <material name="Brown">
    <color rgba="0.870588235294 0.811764705882 0.764705882353 1.0"/>
  </material>
  <material name="Red">
    <color rgba="0.8 0.0 0.0 1.0"/>
  </material>
  <material name="White">
    <color rgba="1.0 1.0 1.0 1.0"/>
  </material>
  <gazebo>
    <plugin filename="libgazebo_ros_control.so" name="gazebo_ros_controller">
      <robotNamespace>/yumi</robotNamespace>
    </plugin>
  </gazebo>
  <link name="yumi_base_link"/>
  <joint name="yumi_base_link_to_body" type="fixed">
    <parent link="yumi_base_link"/>
    <child link="yumi_body"/>
    <origin rpy="0 0 0" xyz="0 0 0"/>
  </joint>
  <link name="yumi_body">
    <inertial>
      <origin rpy="0 0 0" xyz="0 0 0"/>
      <mass value="15"/>
      <inertia ixx="0.5" ixy="0" ixz="0" iyy="0.6" iyz="0" izz="0.3"/>
    </inertial>
    <visual>
      <origin rpy="0 0 0" xyz="0 0 0"/>
      <geometry>
        <mesh filename="package://yumi_drake//yumi_description/meshes/body.obj"/>
      </geometry>
      <material name="Light_Grey"/>
    </visual>
    <collision>
      <origin rpy="0 0 0" xyz="0 0 0"/>
      <geometry>
        <mesh filename="package://yumi_drake//yumi_description/meshes/coarse/body.obj"/>
      </geometry>
      <material name="Light_Grey"/>
    </collision>
  </link>
  <!--///////////////////////////////////// RIGHT ARM ////////////////////////////////  -->
  <!-- joint between body and link_1_r -->
  <!--///////////////////////////////////// LEFT ARM ////////////////////////////////  -->
  <!-- joint between body and link_1_l -->
  <joint name="yumi_robl_joint_1" type="revolute">
    <parent link="yumi_body"/>
    <child link="yumi_link_1_l"/>
    <origin rpy="0.9781 -0.5716 2.3180" xyz="0.05355 0.07250 0.41492"/>
    <axis xyz="0 0 1"/>
    <limit effort="300" lower="-2.94087978961" upper="2.94087978961" velocity="3.14159265359"/>
    <dynamics damping="0.5"/>
  </joint>
  <link name="yumi_link_1_l">
    <inertial>
      <origin rpy="0 0 0" xyz="0 -0.03 0.12"/>
      <mass value="2"/>
      <inertia ixx="0.1" ixy="0" ixz="0" iyy="0.1" iyz="0" izz="0.1"/>
    </inertial>
    <visual>
      <origin rpy="0 0 0" xyz="0 0 0"/>
      <geometry>
        <mesh filename="package://yumi_drake//yumi_description/meshes/link_1.obj"/>
      </geometry>
      <material name="Grey"/>
    </visual>
    <collision>
      <origin rpy="0 0 0" xyz="0 0 0"/>
      <geometry>
        <mesh filename="package://yumi_drake//yumi_description/meshes/coarse/link_1.obj"/>
      </geometry>
      <material name="Grey"/>
    </collision>
  </link>
  <!-- joint between link_1_l and link_2_l -->
  <joint name="yumi_robl_joint_2" type="revolute">
    <parent link="yumi_link_1_l"/>
    <child link="yumi_link_2_l"/>
    <origin rpy="1.57079632679 0.0 0.0" xyz="0.03 0.0 0.1"/>
    <axis xyz="0 0 1"/>
    <limit effort="300" lower="-2.50454747661" upper="0.759218224618" velocity="3.14159265359"/>
    <dynamics damping="0.5"/>
  </joint>
  <link name="yumi_link_2_l">
    <inertial>
      <origin rpy="0 0 0" xyz="0 0 0"/>
      <mass value="2"/>
      <inertia ixx="0.1" ixy="0" ixz="0" iyy="0.1" iyz="0" izz="0.1"/>
    </inertial>
    <visual>
      <origin rpy="0 0 0" xyz="0 0 0"/>
      <geometry>
        <mesh filename="package://yumi_drake//yumi_description/meshes/link_2.obj"/>
      </geometry>
      <material name="Grey"/>
    </visual>
    <collision>
      <origin rpy="0 0 0" xyz="0 0 0"/>
      <geometry>
        <mesh filename="package://yumi_drake//yumi_description/meshes/coarse/link_2.obj"/>
      </geometry>
      <material name="Grey"/>
    </collision>
  </link>
  <!-- joint between link_2_l and link_3_l -->
  <joint name="yumi_robl_joint_3" type="revolute">
    <parent link="yumi_link_2_l"/>
    <child link="yumi_link_3_l"/>
    <origin rpy="-1.57079632679 0.0 0.0" xyz="-0.03 0.17283 0.0"/>
    <axis xyz="0 0 1"/>
    <limit effort="300" lower="-2.94087978961" upper="2.94087978961" velocity="3.14159265359"/>
    <dynamics damping="0.5"/>
  </joint>
  <link name="yumi_link_3_l">
    <inertial>
      <origin rpy="0 0 0" xyz="0 0 0"/>
      <mass value="2"/>
      <inertia ixx="0.1" ixy="0" ixz="0" iyy="0.1" iyz="0" izz="0.1"/>
    </inertial>
    <visual>
      <origin rpy="0 0 0" xyz="0 0 0"/>
      <geometry>
        <mesh filename="package://yumi_drake//yumi_description/meshes/link_3.obj"/>
      </geometry>
      <material name="Grey"/>
    </visual>
    <collision>
      <origin rpy="0 0 0" xyz="0 0 0"/>
      <geometry>
        <mesh filename="package://yumi_drake//yumi_description/meshes/coarse/link_3.obj"/>
      </geometry>
      <material name="Grey"/>
    </collision>
  </link>
  <!-- joint between link_3_l and link_4_l -->
  <joint name="yumi_robl_joint_4" type="revolute">
    <parent link="yumi_link_3_l"/>
    <child link="yumi_link_4_l"/>
    <origin rpy="1.57079632679 -1.57079632679 0.0" xyz="-0.04188 0.0 0.07873"/>
    <axis xyz="0 0 1"/>
    <limit effort="300" lower="-2.15548162621" upper="1.3962634016" velocity="3.14159265359"/>
    <dynamics damping="0.5"/>
  </joint>
  <link name="yumi_link_4_l">
    <inertial>
      <origin rpy="0 0 0" xyz="0 0 0"/>
      <mass value="2"/>
      <inertia ixx="0.1" ixy="0" ixz="0" iyy="0.1" iyz="0" izz="0.1"/>
    </inertial>
    <visual>
      <origin rpy="0 0 0" xyz="0 0 0"/>
      <geometry>
        <mesh filename="package://yumi_drake//yumi_description/meshes/link_4.obj"/>
      </geometry>
      <material name="Grey"/>
    </visual>
    <collision>
      <origin rpy="0 0 0" xyz="0 0 0"/>
      <geometry>
        <mesh filename="package://yumi_drake//yumi_description/meshes/coarse/link_4.obj"/>
      </geometry>
      <material name="Grey"/>
    </collision>
  </link>
  <!-- joint between link_4_l and link_5_l -->
  <joint name="yumi_robl_joint_5" type="revolute">
    <parent link="yumi_link_4_l"/>
    <child link="yumi_link_5_l"/>
    <origin rpy="-1.57079632679 0.0 0.0" xyz="0.0405 0.16461 0.0"/>
    <axis xyz="0 0 1"/>
    <limit effort="300" lower="-5.06145483078" upper="5.06145483078" velocity="6.98131700798"/>
    <dynamics damping="0.5"/>
  </joint>
  <link name="yumi_link_5_l">
    <inertial>
      <origin rpy="0 0 0" xyz="0 0 0"/>
      <mass value="2"/>
      <inertia ixx="0.1" ixy="0" ixz="0" iyy="0.1" iyz="0" izz="0.1"/>
    </inertial>
    <visual>
      <origin rpy="0 0 0" xyz="0 0 0"/>
      <geometry>
        <mesh filename="package://yumi_drake//yumi_description/meshes/link_5.obj"/>
      </geometry>
      <material name="Grey"/>
    </visual>
    <collision>
      <origin rpy="0 0 0" xyz="0 0 0"/>
      <geometry>
        <mesh filename="package://yumi_drake//yumi_description/meshes/coarse/link_5.obj"/>
      </geometry>
      <material name="Grey"/>
    </collision>
  </link>
  <!-- joint between link_5_l and link_6_l -->
  <joint name="yumi_robl_joint_6" type="revolute">
    <parent link="yumi_link_5_l"/>
    <child link="yumi_link_6_l"/>
    <origin rpy="1.57079632679 0.0 0.0" xyz="-0.027 0 0.10039"/>
    <axis xyz="0 0 1"/>
    <limit effort="300" lower="-1.53588974176" upper="2.40855436775" velocity="6.98131700798"/>
    <dynamics damping="0.5"/>
  </joint>
  <link name="yumi_link_6_l">
    <inertial>
      <origin rpy="0 0 0" xyz="0 0 0"/>
      <mass value="2"/>
      <inertia ixx="0.1" ixy="0" ixz="0" iyy="0.1" iyz="0" izz="0.1"/>
    </inertial>
    <visual>
      <origin rpy="0 0 0" xyz="0 0 0"/>
      <geometry>
        <mesh filename="package://yumi_drake//yumi_description/meshes/link_6.obj"/>
      </geometry>
      <material name="Grey"/>
    </visual>
    <collision>
      <origin rpy="0 0 0" xyz="0 0 0"/>
      <geometry>
        <mesh filename="package://yumi_drake//yumi_description/meshes/coarse/link_6.obj"/>
      </geometry>
      <material name="Grey"/>
    </collision>
  </link>
  <!-- joint between link_6_l and link_7_l -->
  <joint name="yumi_robl_joint_7" type="revolute">
    <parent link="yumi_link_6_l"/>
    <child link="yumi_link_7_l"/>
    <origin rpy="-1.57079632679 0.0 0.0" xyz="0.027 0.029 0.0"/>
    <axis xyz="0 0 1"/>
    <limit effort="300" lower="-3.99680398707" upper="3.99680398707" velocity="6.98131700798"/>
    <dynamics damping="0.5"/>
  </joint>
  <link name="yumi_link_7_l">
    <inertial>
      <origin rpy="0 0 0" xyz="0 0 0"/>
      <mass value="2"/>
      <inertia ixx="0.1" ixy="0" ixz="0" iyy="0.1" iyz="0" izz="0.1"/>
    </inertial>
    <visual>
      <origin rpy="0 0 0" xyz="0 0 0"/>
      <geometry>
        <mesh filename="package://yumi_drake//yumi_description/meshes/link_7.obj"/>
      </geometry>
      <material name="Grey"/>
    </visual>
    <collision>
      <origin rpy="0 0 0" xyz="0 0 0"/>
      <geometry>
        <mesh filename="package://yumi_drake//yumi_description/meshes/coarse/link_7.obj"/>
      </geometry>
      <material name="Grey"/>
    </collision>
  </link>
  <!-- Gazebo reference frame -->
  <gazebo reference="yumi_body">
    <material>Gazebo/Ivory</material>
    <mu1>0.2</mu1>
    <mu2>0.2</mu2>
  </gazebo>
  <!--joint between {parent} and base-->
  <!-- body -->
  <gazebo reference="gripper_r_base">
    <material>Gazebo/Light_Grey</material>
    <mu1>0.2</mu1>
    <mu2>0.2</mu2>
  </gazebo>
  <!--joint between {parent} and base-->
  <joint name="yumi_link_7_l_joint" type="fixed">
    <origin rpy="0 0 3.14159265359" xyz="0 0 0.007"/>
    <parent link="yumi_link_7_l"/>
    <child link="gripper_l_base"/>
  </joint>
  <link name="gripper_l_base">
    <inertial>
      <origin rpy="0 0 0" xyz="0 0 0"/>
      <mass value="0.2"/>
      <inertia ixx="0.0001" ixy="0" ixz="0" iyy="0.0001" iyz="0" izz="0.0001"/>
    </inertial>
    <visual>
      <origin rpy="0 0 0" xyz="0 0 0"/>
      <geometry>
        <mesh filename="package://yumi_drake//yumi_description/meshes/gripper/base.obj"/>
      </geometry>
      <material name="Light_Grey"/>
    </visual>
    <collision>
      <origin rpy="0 0 0" xyz="0 0 0"/>
      <geometry>
        <mesh filename="package://yumi_drake//yumi_description/meshes/gripper/coarse/base.obj"/>
      </geometry>
      <material name="Light_Grey"/>
    </collision>
  </link>
  <!-- joint between base and right finger -->
  <joint name="gripper_l_joint" type="fixed">
    <parent link="gripper_l_base"/>
    <child link="gripper_l_finger_r"/>
    <origin rpy="0 0 0" xyz="0 -0.0065 0.0837"/>
    <axis xyz="-1 0 0"/>
    <limit effort="20" lower="0" upper="0.025" velocity="2"/>
    <dynamics damping="1.0"/>
  </joint>
  <link name="gripper_l_finger_r">
    <inertial>
      <origin rpy="0 0 0" xyz="0 0 0"/>
      <mass value="0.01"/>
      <inertia ixx="0.000001" ixy="0" ixz="0" iyy="0.000001" iyz="0" izz="0.000001"/>
    </inertial>
    <visual>
      <origin rpy="0 0 0" xyz="0 0 0"/>
      <geometry>
        <mesh filename="package://yumi_drake//yumi_description/meshes/gripper/finger.obj"/>
      </geometry>
      <material name="Blue"/>
    </visual>
    <collision>
      <origin rpy="0 0 0" xyz="0 0 0"/>
      <geometry>
        <mesh filename="package://yumi_drake//yumi_description/meshes/gripper/coarse/finger.obj"/>
      </geometry>
      <material name="Blue"/>
    </collision>
  </link>
  <!-- joint between base and left finger -->
  <joint name="gripper_l_joint_m" type="fixed">
    <parent link="gripper_l_base"/>
    <child link="gripper_l_finger_l"/>
    <origin rpy="0 0 3.14159265359" xyz="0 0.0065 0.0837"/>
    <axis xyz="-1 0 0"/>
    <limit effort="20" lower="0" upper="0.025" velocity="2"/>
    <dynamics damping="1.0"/>
  </joint>
  <link name="gripper_l_finger_l">
    <inertial>
      <origin rpy="0 0 0" xyz="0 0 0"/>
      <mass value="0.01"/>
      <inertia ixx="0.000001" ixy="0" ixz="0" iyy="0.000001" iyz="0" izz="0.000001"/>
    </inertial>
    <visual>
      <origin rpy="0 0 0" xyz="0 0 0"/>
      <geometry>
        <mesh filename="package://yumi_drake//yumi_description/meshes/gripper/finger.obj"/>
      </geometry>
      <material name="Blue"/>
    </visual>
    <collision>
      <origin rpy="0 0 0" xyz="0 0 0"/>
      <geometry>
        <mesh filename="package://yumi_drake//yumi_description/meshes/gripper/coarse/finger.obj"/>
      </geometry>
      <material name="Blue"/>
    </collision>
  </link>
  <!-- body -->
  <gazebo reference="gripper_l_base">
    <material>Gazebo/Light_Grey</material>
    <mu1>0.2</mu1>
    <mu2>0.2</mu2>
  </gazebo>
  <!-- Pure YuMi URDF, with no joints connecting it to any other robot or pedestal. Neither accessories. -->
</robot>
